{"level":"ERROR","location":"[exception:108] fyers_logger","message":"('Connection aborted.', RemoteDisconnected('Remote end closed connection without response'))","timestamp":"2024-10-02 12:06:25,987+0530","service":"FyersDataSocket","exception":"Traceback (most recent call last):\n  File \"/usr/local/lib/python3.8/site-packages/urllib3/connectionpool.py\", line 715, in urlopen\n    httplib_response = self._make_request(\n  File \"/usr/local/lib/python3.8/site-packages/urllib3/connectionpool.py\", line 467, in _make_request\n    six.raise_from(e, None)\n  File \"<string>\", line 3, in raise_from\n  File \"/usr/local/lib/python3.8/site-packages/urllib3/connectionpool.py\", line 462, in _make_request\n    httplib_response = conn.getresponse()\n  File \"/usr/local/lib/python3.8/http/client.py\", line 1348, in getresponse\n    response.begin()\n  File \"/usr/local/lib/python3.8/http/client.py\", line 316, in begin\n    version, status, reason = self._read_status()\n  File \"/usr/local/lib/python3.8/http/client.py\", line 285, in _read_status\n    raise RemoteDisconnected(\"Remote end closed connection without\"\nhttp.client.RemoteDisconnected: Remote end closed connection without response\n\nDuring handling of the above exception, another exception occurred:\n\nTraceback (most recent call last):\n  File \"/usr/local/lib/python3.8/site-packages/requests/adapters.py\", line 486, in send\n    resp = conn.urlopen(\n  File \"/usr/local/lib/python3.8/site-packages/urllib3/connectionpool.py\", line 799, in urlopen\n    retries = retries.increment(\n  File \"/usr/local/lib/python3.8/site-packages/urllib3/util/retry.py\", line 550, in increment\n    raise six.reraise(type(error), error, _stacktrace)\n  File \"/usr/local/lib/python3.8/site-packages/urllib3/packages/six.py\", line 769, in reraise\n    raise value.with_traceback(tb)\n  File \"/usr/local/lib/python3.8/site-packages/urllib3/connectionpool.py\", line 715, in urlopen\n    httplib_response = self._make_request(\n  File \"/usr/local/lib/python3.8/site-packages/urllib3/connectionpool.py\", line 467, in _make_request\n    six.raise_from(e, None)\n  File \"<string>\", line 3, in raise_from\n  File \"/usr/local/lib/python3.8/site-packages/urllib3/connectionpool.py\", line 462, in _make_request\n    httplib_response = conn.getresponse()\n  File \"/usr/local/lib/python3.8/http/client.py\", line 1348, in getresponse\n    response.begin()\n  File \"/usr/local/lib/python3.8/http/client.py\", line 316, in begin\n    version, status, reason = self._read_status()\n  File \"/usr/local/lib/python3.8/http/client.py\", line 285, in _read_status\n    raise RemoteDisconnected(\"Remote end closed connection without\"\nurllib3.exceptions.ProtocolError: ('Connection aborted.', RemoteDisconnected('Remote end closed connection without response'))\n\nDuring handling of the above exception, another exception occurred:\n\nTraceback (most recent call last):\n  File \"/usr/local/lib/python3.8/site-packages/fyers_apiv3/FyersWebsocket/data_ws.py\", line 63, in symbol_to_hsmtoken\n    response = requests.post(\n  File \"/usr/local/lib/python3.8/site-packages/requests/api.py\", line 115, in post\n    return request(\"post\", url, data=data, json=json, **kwargs)\n  File \"/usr/local/lib/python3.8/site-packages/requests/api.py\", line 59, in request\n    return session.request(method=method, url=url, **kwargs)\n  File \"/usr/local/lib/python3.8/site-packages/requests/sessions.py\", line 589, in request\n    resp = self.send(prep, **send_kwargs)\n  File \"/usr/local/lib/python3.8/site-packages/requests/sessions.py\", line 703, in send\n    r = adapter.send(request, **kwargs)\n  File \"/usr/local/lib/python3.8/site-packages/requests/adapters.py\", line 501, in send\n    raise ConnectionError(err, request=request)\nrequests.exceptions.ConnectionError: ('Connection aborted.', RemoteDisconnected('Remote end closed connection without response'))","exception_name":"ConnectionError"}
{"level":"ERROR","location":"[exception:108] fyers_logger","message":"'NoneType' object is not subscriptable","timestamp":"2024-10-02 12:06:25,998+0530","service":"FyersDataSocket","exception":"Traceback (most recent call last):\n  File \"/usr/local/lib/python3.8/site-packages/fyers_apiv3/FyersWebsocket/data_ws.py\", line 1333, in __symbol_conversion\n    if symbol_value[3] != \"\":\nTypeError: 'NoneType' object is not subscriptable","exception_name":"TypeError"}
{"level":"ERROR","location":"[exception:108] fyers_logger","message":"'NoneType' object has no attribute 'keys'","timestamp":"2024-10-02 12:06:25,999+0530","service":"FyersDataSocket","exception":"Traceback (most recent call last):\n  File \"/usr/local/lib/python3.8/site-packages/fyers_apiv3/FyersWebsocket/data_ws.py\", line 1741, in unsubscribe\n    self.unsub_symbol = list(self.channel_symbol.keys())\nAttributeError: 'NoneType' object has no attribute 'keys'","exception_name":"AttributeError"}
{"level":"ERROR","location":"[<lambda>:1663] data_ws","message":"Connection to remote host was lost.","timestamp":"2024-10-02 12:06:53,456+0530","service":"FyersDataSocket"}
{"level":"ERROR","location":"[<lambda>:1663] data_ws","message":"[Errno -2] Name or service not known","timestamp":"2024-10-02 12:06:58,473+0530","service":"FyersDataSocket"}
{"level":"ERROR","location":"[exception:108] fyers_logger","message":"HTTPSConnectionPool(host='api-t1.fyers.in', port=443): Max retries exceeded with url: /data/symbol-token (Caused by NewConnectionError('<urllib3.connection.HTTPSConnection object at 0x7fbf0f153970>: Failed to establish a new connection: [Errno -2] Name or service not known'))","timestamp":"2024-10-02 12:07:00,477+0530","service":"FyersDataSocket","exception":"Traceback (most recent call last):\n  File \"/usr/local/lib/python3.8/site-packages/asgiref/sync.py\", line 349, in main_wrap\n    raise exc_info[1]\n  File \"/usr/local/lib/python3.8/site-packages/websocket/_app.py\", line 428, in setSock\n    dispatcher.read(self.sock.sock, read, check)\n  File \"/usr/local/lib/python3.8/site-packages/websocket/_app.py\", line 99, in read\n    if not read_callback():\n  File \"/usr/local/lib/python3.8/site-packages/websocket/_app.py\", line 442, in read\n    raise e\n  File \"/usr/local/lib/python3.8/site-packages/websocket/_app.py\", line 437, in read\n    op_code, frame = self.sock.recv_data_frame(True)\n  File \"/usr/local/lib/python3.8/site-packages/websocket/_core.py\", line 406, in recv_data_frame\n    frame = self.recv_frame()\n  File \"/usr/local/lib/python3.8/site-packages/websocket/_core.py\", line 445, in recv_frame\n    return self.frame_buffer.recv_frame()\n  File \"/usr/local/lib/python3.8/site-packages/websocket/_abnf.py\", line 338, in recv_frame\n    self.recv_header()\n  File \"/usr/local/lib/python3.8/site-packages/websocket/_abnf.py\", line 294, in recv_header\n    header = self.recv_strict(2)\n  File \"/usr/local/lib/python3.8/site-packages/websocket/_abnf.py\", line 373, in recv_strict\n    bytes_ = self.recv(min(16384, shortage))\n  File \"/usr/local/lib/python3.8/site-packages/websocket/_core.py\", line 529, in _recv\n    return recv(self.sock, bufsize)\n  File \"/usr/local/lib/python3.8/site-packages/websocket/_socket.py\", line 122, in recv\n    raise WebSocketConnectionClosedException(\nwebsocket._exceptions.WebSocketConnectionClosedException: Connection to remote host was lost.\n\nDuring handling of the above exception, another exception occurred:\n\nTraceback (most recent call last):\n  File \"/usr/local/lib/python3.8/site-packages/urllib3/connection.py\", line 174, in _new_conn\n    conn = connection.create_connection(\n  File \"/usr/local/lib/python3.8/site-packages/urllib3/util/connection.py\", line 72, in create_connection\n    for res in socket.getaddrinfo(host, port, family, socket.SOCK_STREAM):\n  File \"/usr/local/lib/python3.8/socket.py\", line 918, in getaddrinfo\n    for res in _socket.getaddrinfo(host, port, family, type, proto, flags):\nsocket.gaierror: [Errno -2] Name or service not known\n\nDuring handling of the above exception, another exception occurred:\n\nTraceback (most recent call last):\n  File \"/usr/local/lib/python3.8/site-packages/urllib3/connectionpool.py\", line 715, in urlopen\n    httplib_response = self._make_request(\n  File \"/usr/local/lib/python3.8/site-packages/urllib3/connectionpool.py\", line 404, in _make_request\n    self._validate_conn(conn)\n  File \"/usr/local/lib/python3.8/site-packages/urllib3/connectionpool.py\", line 1058, in _validate_conn\n    conn.connect()\n  File \"/usr/local/lib/python3.8/site-packages/urllib3/connection.py\", line 363, in connect\n    self.sock = conn = self._new_conn()\n  File \"/usr/local/lib/python3.8/site-packages/urllib3/connection.py\", line 186, in _new_conn\n    raise NewConnectionError(\nurllib3.exceptions.NewConnectionError: <urllib3.connection.HTTPSConnection object at 0x7fbf0f153970>: Failed to establish a new connection: [Errno -2] Name or service not known\n\nDuring handling of the above exception, another exception occurred:\n\nTraceback (most recent call last):\n  File \"/usr/local/lib/python3.8/site-packages/requests/adapters.py\", line 486, in send\n    resp = conn.urlopen(\n  File \"/usr/local/lib/python3.8/site-packages/urllib3/connectionpool.py\", line 799, in urlopen\n    retries = retries.increment(\n  File \"/usr/local/lib/python3.8/site-packages/urllib3/util/retry.py\", line 592, in increment\n    raise MaxRetryError(_pool, url, error or ResponseError(cause))\nurllib3.exceptions.MaxRetryError: HTTPSConnectionPool(host='api-t1.fyers.in', port=443): Max retries exceeded with url: /data/symbol-token (Caused by NewConnectionError('<urllib3.connection.HTTPSConnection object at 0x7fbf0f153970>: Failed to establish a new connection: [Errno -2] Name or service not known'))\n\nDuring handling of the above exception, another exception occurred:\n\nTraceback (most recent call last):\n  File \"/usr/local/lib/python3.8/site-packages/fyers_apiv3/FyersWebsocket/data_ws.py\", line 63, in symbol_to_hsmtoken\n    response = requests.post(\n  File \"/usr/local/lib/python3.8/site-packages/requests/api.py\", line 115, in post\n    return request(\"post\", url, data=data, json=json, **kwargs)\n  File \"/usr/local/lib/python3.8/site-packages/requests/api.py\", line 59, in request\n    return session.request(method=method, url=url, **kwargs)\n  File \"/usr/local/lib/python3.8/site-packages/requests/sessions.py\", line 589, in request\n    resp = self.send(prep, **send_kwargs)\n  File \"/usr/local/lib/python3.8/site-packages/requests/sessions.py\", line 703, in send\n    r = adapter.send(request, **kwargs)\n  File \"/usr/local/lib/python3.8/site-packages/requests/adapters.py\", line 519, in send\n    raise ConnectionError(e, request=request)\nrequests.exceptions.ConnectionError: HTTPSConnectionPool(host='api-t1.fyers.in', port=443): Max retries exceeded with url: /data/symbol-token (Caused by NewConnectionError('<urllib3.connection.HTTPSConnection object at 0x7fbf0f153970>: Failed to establish a new connection: [Errno -2] Name or service not known'))","exception_name":"ConnectionError"}
{"level":"ERROR","location":"[exception:108] fyers_logger","message":"'NoneType' object is not subscriptable","timestamp":"2024-10-02 12:07:00,485+0530","service":"FyersDataSocket","exception":"Traceback (most recent call last):\n  File \"/usr/local/lib/python3.8/site-packages/asgiref/sync.py\", line 349, in main_wrap\n    raise exc_info[1]\n  File \"/usr/local/lib/python3.8/site-packages/websocket/_app.py\", line 428, in setSock\n    dispatcher.read(self.sock.sock, read, check)\n  File \"/usr/local/lib/python3.8/site-packages/websocket/_app.py\", line 99, in read\n    if not read_callback():\n  File \"/usr/local/lib/python3.8/site-packages/websocket/_app.py\", line 442, in read\n    raise e\n  File \"/usr/local/lib/python3.8/site-packages/websocket/_app.py\", line 437, in read\n    op_code, frame = self.sock.recv_data_frame(True)\n  File \"/usr/local/lib/python3.8/site-packages/websocket/_core.py\", line 406, in recv_data_frame\n    frame = self.recv_frame()\n  File \"/usr/local/lib/python3.8/site-packages/websocket/_core.py\", line 445, in recv_frame\n    return self.frame_buffer.recv_frame()\n  File \"/usr/local/lib/python3.8/site-packages/websocket/_abnf.py\", line 338, in recv_frame\n    self.recv_header()\n  File \"/usr/local/lib/python3.8/site-packages/websocket/_abnf.py\", line 294, in recv_header\n    header = self.recv_strict(2)\n  File \"/usr/local/lib/python3.8/site-packages/websocket/_abnf.py\", line 373, in recv_strict\n    bytes_ = self.recv(min(16384, shortage))\n  File \"/usr/local/lib/python3.8/site-packages/websocket/_core.py\", line 529, in _recv\n    return recv(self.sock, bufsize)\n  File \"/usr/local/lib/python3.8/site-packages/websocket/_socket.py\", line 122, in recv\n    raise WebSocketConnectionClosedException(\nwebsocket._exceptions.WebSocketConnectionClosedException: Connection to remote host was lost.\n\nDuring handling of the above exception, another exception occurred:\n\nTraceback (most recent call last):\n  File \"/usr/local/lib/python3.8/site-packages/fyers_apiv3/FyersWebsocket/data_ws.py\", line 1333, in __symbol_conversion\n    if symbol_value[3] != \"\":\nTypeError: 'NoneType' object is not subscriptable","exception_name":"TypeError"}
{"level":"ERROR","location":"[<lambda>:1663] data_ws","message":"[Errno -2] Name or service not known","timestamp":"2024-10-02 12:07:03,488+0530","service":"FyersDataSocket"}
{"level":"ERROR","location":"[exception:108] fyers_logger","message":"HTTPSConnectionPool(host='api-t1.fyers.in', port=443): Max retries exceeded with url: /data/symbol-token (Caused by NewConnectionError('<urllib3.connection.HTTPSConnection object at 0x7fbf0f19f130>: Failed to establish a new connection: [Errno -2] Name or service not known'))","timestamp":"2024-10-02 12:07:05,488+0530","service":"FyersDataSocket","exception":"Traceback (most recent call last):\n  File \"/usr/local/lib/python3.8/site-packages/websocket/_http.py\", line 155, in _get_addrinfo_list\n    addrinfo_list = socket.getaddrinfo(\n  File \"/usr/local/lib/python3.8/socket.py\", line 918, in getaddrinfo\n    for res in _socket.getaddrinfo(host, port, family, type, proto, flags):\nsocket.gaierror: [Errno -2] Name or service not known\n\nDuring handling of the above exception, another exception occurred:\n\nTraceback (most recent call last):\n  File \"/usr/local/lib/python3.8/site-packages/asgiref/sync.py\", line 349, in main_wrap\n    raise exc_info[1]\n  File \"/usr/local/lib/python3.8/site-packages/websocket/_app.py\", line 412, in setSock\n    self.sock.connect(\n  File \"/usr/local/lib/python3.8/site-packages/websocket/_core.py\", line 249, in connect\n    self.sock, addrs = connect(url, self.sock_opt, proxy_info(**options),\n  File \"/usr/local/lib/python3.8/site-packages/websocket/_http.py\", line 122, in connect\n    addrinfo_list, need_tunnel, auth = _get_addrinfo_list(\n  File \"/usr/local/lib/python3.8/site-packages/websocket/_http.py\", line 167, in _get_addrinfo_list\n    raise WebSocketAddressException(e)\nwebsocket._exceptions.WebSocketAddressException: [Errno -2] Name or service not known\n\nDuring handling of the above exception, another exception occurred:\n\nTraceback (most recent call last):\n  File \"/usr/local/lib/python3.8/site-packages/urllib3/connection.py\", line 174, in _new_conn\n    conn = connection.create_connection(\n  File \"/usr/local/lib/python3.8/site-packages/urllib3/util/connection.py\", line 72, in create_connection\n    for res in socket.getaddrinfo(host, port, family, socket.SOCK_STREAM):\n  File \"/usr/local/lib/python3.8/socket.py\", line 918, in getaddrinfo\n    for res in _socket.getaddrinfo(host, port, family, type, proto, flags):\nsocket.gaierror: [Errno -2] Name or service not known\n\nDuring handling of the above exception, another exception occurred:\n\nTraceback (most recent call last):\n  File \"/usr/local/lib/python3.8/site-packages/urllib3/connectionpool.py\", line 715, in urlopen\n    httplib_response = self._make_request(\n  File \"/usr/local/lib/python3.8/site-packages/urllib3/connectionpool.py\", line 404, in _make_request\n    self._validate_conn(conn)\n  File \"/usr/local/lib/python3.8/site-packages/urllib3/connectionpool.py\", line 1058, in _validate_conn\n    conn.connect()\n  File \"/usr/local/lib/python3.8/site-packages/urllib3/connection.py\", line 363, in connect\n    self.sock = conn = self._new_conn()\n  File \"/usr/local/lib/python3.8/site-packages/urllib3/connection.py\", line 186, in _new_conn\n    raise NewConnectionError(\nurllib3.exceptions.NewConnectionError: <urllib3.connection.HTTPSConnection object at 0x7fbf0f19f130>: Failed to establish a new connection: [Errno -2] Name or service not known\n\nDuring handling of the above exception, another exception occurred:\n\nTraceback (most recent call last):\n  File \"/usr/local/lib/python3.8/site-packages/requests/adapters.py\", line 486, in send\n    resp = conn.urlopen(\n  File \"/usr/local/lib/python3.8/site-packages/urllib3/connectionpool.py\", line 799, in urlopen\n    retries = retries.increment(\n  File \"/usr/local/lib/python3.8/site-packages/urllib3/util/retry.py\", line 592, in increment\n    raise MaxRetryError(_pool, url, error or ResponseError(cause))\nurllib3.exceptions.MaxRetryError: HTTPSConnectionPool(host='api-t1.fyers.in', port=443): Max retries exceeded with url: /data/symbol-token (Caused by NewConnectionError('<urllib3.connection.HTTPSConnection object at 0x7fbf0f19f130>: Failed to establish a new connection: [Errno -2] Name or service not known'))\n\nDuring handling of the above exception, another exception occurred:\n\nTraceback (most recent call last):\n  File \"/usr/local/lib/python3.8/site-packages/fyers_apiv3/FyersWebsocket/data_ws.py\", line 63, in symbol_to_hsmtoken\n    response = requests.post(\n  File \"/usr/local/lib/python3.8/site-packages/requests/api.py\", line 115, in post\n    return request(\"post\", url, data=data, json=json, **kwargs)\n  File \"/usr/local/lib/python3.8/site-packages/requests/api.py\", line 59, in request\n    return session.request(method=method, url=url, **kwargs)\n  File \"/usr/local/lib/python3.8/site-packages/requests/sessions.py\", line 589, in request\n    resp = self.send(prep, **send_kwargs)\n  File \"/usr/local/lib/python3.8/site-packages/requests/sessions.py\", line 703, in send\n    r = adapter.send(request, **kwargs)\n  File \"/usr/local/lib/python3.8/site-packages/requests/adapters.py\", line 519, in send\n    raise ConnectionError(e, request=request)\nrequests.exceptions.ConnectionError: HTTPSConnectionPool(host='api-t1.fyers.in', port=443): Max retries exceeded with url: /data/symbol-token (Caused by NewConnectionError('<urllib3.connection.HTTPSConnection object at 0x7fbf0f19f130>: Failed to establish a new connection: [Errno -2] Name or service not known'))","exception_name":"ConnectionError"}
{"level":"ERROR","location":"[exception:108] fyers_logger","message":"'NoneType' object is not subscriptable","timestamp":"2024-10-02 12:07:05,490+0530","service":"FyersDataSocket","exception":"Traceback (most recent call last):\n  File \"/usr/local/lib/python3.8/site-packages/websocket/_http.py\", line 155, in _get_addrinfo_list\n    addrinfo_list = socket.getaddrinfo(\n  File \"/usr/local/lib/python3.8/socket.py\", line 918, in getaddrinfo\n    for res in _socket.getaddrinfo(host, port, family, type, proto, flags):\nsocket.gaierror: [Errno -2] Name or service not known\n\nDuring handling of the above exception, another exception occurred:\n\nTraceback (most recent call last):\n  File \"/usr/local/lib/python3.8/site-packages/asgiref/sync.py\", line 349, in main_wrap\n    raise exc_info[1]\n  File \"/usr/local/lib/python3.8/site-packages/websocket/_app.py\", line 412, in setSock\n    self.sock.connect(\n  File \"/usr/local/lib/python3.8/site-packages/websocket/_core.py\", line 249, in connect\n    self.sock, addrs = connect(url, self.sock_opt, proxy_info(**options),\n  File \"/usr/local/lib/python3.8/site-packages/websocket/_http.py\", line 122, in connect\n    addrinfo_list, need_tunnel, auth = _get_addrinfo_list(\n  File \"/usr/local/lib/python3.8/site-packages/websocket/_http.py\", line 167, in _get_addrinfo_list\n    raise WebSocketAddressException(e)\nwebsocket._exceptions.WebSocketAddressException: [Errno -2] Name or service not known\n\nDuring handling of the above exception, another exception occurred:\n\nTraceback (most recent call last):\n  File \"/usr/local/lib/python3.8/site-packages/fyers_apiv3/FyersWebsocket/data_ws.py\", line 1333, in __symbol_conversion\n    if symbol_value[3] != \"\":\nTypeError: 'NoneType' object is not subscriptable","exception_name":"TypeError"}
{"level":"ERROR","location":"[<lambda>:1663] data_ws","message":"[Errno -2] Name or service not known","timestamp":"2024-10-02 12:07:08,504+0530","service":"FyersDataSocket"}
{"level":"ERROR","location":"[exception:108] fyers_logger","message":"HTTPSConnectionPool(host='api-t1.fyers.in', port=443): Max retries exceeded with url: /data/symbol-token (Caused by NewConnectionError('<urllib3.connection.HTTPSConnection object at 0x7fbf0f1530d0>: Failed to establish a new connection: [Errno -2] Name or service not known'))","timestamp":"2024-10-02 12:07:10,504+0530","service":"FyersDataSocket","exception":"Traceback (most recent call last):\n  File \"/usr/local/lib/python3.8/site-packages/websocket/_http.py\", line 155, in _get_addrinfo_list\n    addrinfo_list = socket.getaddrinfo(\n  File \"/usr/local/lib/python3.8/socket.py\", line 918, in getaddrinfo\n    for res in _socket.getaddrinfo(host, port, family, type, proto, flags):\nsocket.gaierror: [Errno -2] Name or service not known\n\nDuring handling of the above exception, another exception occurred:\n\nTraceback (most recent call last):\n  File \"/usr/local/lib/python3.8/site-packages/asgiref/sync.py\", line 349, in main_wrap\n    raise exc_info[1]\n  File \"/usr/local/lib/python3.8/site-packages/websocket/_app.py\", line 412, in setSock\n    self.sock.connect(\n  File \"/usr/local/lib/python3.8/site-packages/websocket/_core.py\", line 249, in connect\n    self.sock, addrs = connect(url, self.sock_opt, proxy_info(**options),\n  File \"/usr/local/lib/python3.8/site-packages/websocket/_http.py\", line 122, in connect\n    addrinfo_list, need_tunnel, auth = _get_addrinfo_list(\n  File \"/usr/local/lib/python3.8/site-packages/websocket/_http.py\", line 167, in _get_addrinfo_list\n    raise WebSocketAddressException(e)\nwebsocket._exceptions.WebSocketAddressException: [Errno -2] Name or service not known\n\nDuring handling of the above exception, another exception occurred:\n\nTraceback (most recent call last):\n  File \"/usr/local/lib/python3.8/site-packages/urllib3/connection.py\", line 174, in _new_conn\n    conn = connection.create_connection(\n  File \"/usr/local/lib/python3.8/site-packages/urllib3/util/connection.py\", line 72, in create_connection\n    for res in socket.getaddrinfo(host, port, family, socket.SOCK_STREAM):\n  File \"/usr/local/lib/python3.8/socket.py\", line 918, in getaddrinfo\n    for res in _socket.getaddrinfo(host, port, family, type, proto, flags):\nsocket.gaierror: [Errno -2] Name or service not known\n\nDuring handling of the above exception, another exception occurred:\n\nTraceback (most recent call last):\n  File \"/usr/local/lib/python3.8/site-packages/urllib3/connectionpool.py\", line 715, in urlopen\n    httplib_response = self._make_request(\n  File \"/usr/local/lib/python3.8/site-packages/urllib3/connectionpool.py\", line 404, in _make_request\n    self._validate_conn(conn)\n  File \"/usr/local/lib/python3.8/site-packages/urllib3/connectionpool.py\", line 1058, in _validate_conn\n    conn.connect()\n  File \"/usr/local/lib/python3.8/site-packages/urllib3/connection.py\", line 363, in connect\n    self.sock = conn = self._new_conn()\n  File \"/usr/local/lib/python3.8/site-packages/urllib3/connection.py\", line 186, in _new_conn\n    raise NewConnectionError(\nurllib3.exceptions.NewConnectionError: <urllib3.connection.HTTPSConnection object at 0x7fbf0f1530d0>: Failed to establish a new connection: [Errno -2] Name or service not known\n\nDuring handling of the above exception, another exception occurred:\n\nTraceback (most recent call last):\n  File \"/usr/local/lib/python3.8/site-packages/requests/adapters.py\", line 486, in send\n    resp = conn.urlopen(\n  File \"/usr/local/lib/python3.8/site-packages/urllib3/connectionpool.py\", line 799, in urlopen\n    retries = retries.increment(\n  File \"/usr/local/lib/python3.8/site-packages/urllib3/util/retry.py\", line 592, in increment\n    raise MaxRetryError(_pool, url, error or ResponseError(cause))\nurllib3.exceptions.MaxRetryError: HTTPSConnectionPool(host='api-t1.fyers.in', port=443): Max retries exceeded with url: /data/symbol-token (Caused by NewConnectionError('<urllib3.connection.HTTPSConnection object at 0x7fbf0f1530d0>: Failed to establish a new connection: [Errno -2] Name or service not known'))\n\nDuring handling of the above exception, another exception occurred:\n\nTraceback (most recent call last):\n  File \"/usr/local/lib/python3.8/site-packages/fyers_apiv3/FyersWebsocket/data_ws.py\", line 63, in symbol_to_hsmtoken\n    response = requests.post(\n  File \"/usr/local/lib/python3.8/site-packages/requests/api.py\", line 115, in post\n    return request(\"post\", url, data=data, json=json, **kwargs)\n  File \"/usr/local/lib/python3.8/site-packages/requests/api.py\", line 59, in request\n    return session.request(method=method, url=url, **kwargs)\n  File \"/usr/local/lib/python3.8/site-packages/requests/sessions.py\", line 589, in request\n    resp = self.send(prep, **send_kwargs)\n  File \"/usr/local/lib/python3.8/site-packages/requests/sessions.py\", line 703, in send\n    r = adapter.send(request, **kwargs)\n  File \"/usr/local/lib/python3.8/site-packages/requests/adapters.py\", line 519, in send\n    raise ConnectionError(e, request=request)\nrequests.exceptions.ConnectionError: HTTPSConnectionPool(host='api-t1.fyers.in', port=443): Max retries exceeded with url: /data/symbol-token (Caused by NewConnectionError('<urllib3.connection.HTTPSConnection object at 0x7fbf0f1530d0>: Failed to establish a new connection: [Errno -2] Name or service not known'))","exception_name":"ConnectionError"}
{"level":"ERROR","location":"[exception:108] fyers_logger","message":"'NoneType' object is not subscriptable","timestamp":"2024-10-02 12:07:10,505+0530","service":"FyersDataSocket","exception":"Traceback (most recent call last):\n  File \"/usr/local/lib/python3.8/site-packages/websocket/_http.py\", line 155, in _get_addrinfo_list\n    addrinfo_list = socket.getaddrinfo(\n  File \"/usr/local/lib/python3.8/socket.py\", line 918, in getaddrinfo\n    for res in _socket.getaddrinfo(host, port, family, type, proto, flags):\nsocket.gaierror: [Errno -2] Name or service not known\n\nDuring handling of the above exception, another exception occurred:\n\nTraceback (most recent call last):\n  File \"/usr/local/lib/python3.8/site-packages/asgiref/sync.py\", line 349, in main_wrap\n    raise exc_info[1]\n  File \"/usr/local/lib/python3.8/site-packages/websocket/_app.py\", line 412, in setSock\n    self.sock.connect(\n  File \"/usr/local/lib/python3.8/site-packages/websocket/_core.py\", line 249, in connect\n    self.sock, addrs = connect(url, self.sock_opt, proxy_info(**options),\n  File \"/usr/local/lib/python3.8/site-packages/websocket/_http.py\", line 122, in connect\n    addrinfo_list, need_tunnel, auth = _get_addrinfo_list(\n  File \"/usr/local/lib/python3.8/site-packages/websocket/_http.py\", line 167, in _get_addrinfo_list\n    raise WebSocketAddressException(e)\nwebsocket._exceptions.WebSocketAddressException: [Errno -2] Name or service not known\n\nDuring handling of the above exception, another exception occurred:\n\nTraceback (most recent call last):\n  File \"/usr/local/lib/python3.8/site-packages/fyers_apiv3/FyersWebsocket/data_ws.py\", line 1333, in __symbol_conversion\n    if symbol_value[3] != \"\":\nTypeError: 'NoneType' object is not subscriptable","exception_name":"TypeError"}
{"level":"ERROR","location":"[<lambda>:1663] data_ws","message":"[Errno -2] Name or service not known","timestamp":"2024-10-02 12:07:13,519+0530","service":"FyersDataSocket"}
{"level":"ERROR","location":"[exception:108] fyers_logger","message":"HTTPSConnectionPool(host='api-t1.fyers.in', port=443): Max retries exceeded with url: /data/symbol-token (Caused by NewConnectionError('<urllib3.connection.HTTPSConnection object at 0x7fbf0f153d00>: Failed to establish a new connection: [Errno -2] Name or service not known'))","timestamp":"2024-10-02 12:07:15,523+0530","service":"FyersDataSocket","exception":"Traceback (most recent call last):\n  File \"/usr/local/lib/python3.8/site-packages/websocket/_http.py\", line 155, in _get_addrinfo_list\n    addrinfo_list = socket.getaddrinfo(\n  File \"/usr/local/lib/python3.8/socket.py\", line 918, in getaddrinfo\n    for res in _socket.getaddrinfo(host, port, family, type, proto, flags):\nsocket.gaierror: [Errno -2] Name or service not known\n\nDuring handling of the above exception, another exception occurred:\n\nTraceback (most recent call last):\n  File \"/usr/local/lib/python3.8/site-packages/asgiref/sync.py\", line 349, in main_wrap\n    raise exc_info[1]\n  File \"/usr/local/lib/python3.8/site-packages/websocket/_app.py\", line 412, in setSock\n    self.sock.connect(\n  File \"/usr/local/lib/python3.8/site-packages/websocket/_core.py\", line 249, in connect\n    self.sock, addrs = connect(url, self.sock_opt, proxy_info(**options),\n  File \"/usr/local/lib/python3.8/site-packages/websocket/_http.py\", line 122, in connect\n    addrinfo_list, need_tunnel, auth = _get_addrinfo_list(\n  File \"/usr/local/lib/python3.8/site-packages/websocket/_http.py\", line 167, in _get_addrinfo_list\n    raise WebSocketAddressException(e)\nwebsocket._exceptions.WebSocketAddressException: [Errno -2] Name or service not known\n\nDuring handling of the above exception, another exception occurred:\n\nTraceback (most recent call last):\n  File \"/usr/local/lib/python3.8/site-packages/urllib3/connection.py\", line 174, in _new_conn\n    conn = connection.create_connection(\n  File \"/usr/local/lib/python3.8/site-packages/urllib3/util/connection.py\", line 72, in create_connection\n    for res in socket.getaddrinfo(host, port, family, socket.SOCK_STREAM):\n  File \"/usr/local/lib/python3.8/socket.py\", line 918, in getaddrinfo\n    for res in _socket.getaddrinfo(host, port, family, type, proto, flags):\nsocket.gaierror: [Errno -2] Name or service not known\n\nDuring handling of the above exception, another exception occurred:\n\nTraceback (most recent call last):\n  File \"/usr/local/lib/python3.8/site-packages/urllib3/connectionpool.py\", line 715, in urlopen\n    httplib_response = self._make_request(\n  File \"/usr/local/lib/python3.8/site-packages/urllib3/connectionpool.py\", line 404, in _make_request\n    self._validate_conn(conn)\n  File \"/usr/local/lib/python3.8/site-packages/urllib3/connectionpool.py\", line 1058, in _validate_conn\n    conn.connect()\n  File \"/usr/local/lib/python3.8/site-packages/urllib3/connection.py\", line 363, in connect\n    self.sock = conn = self._new_conn()\n  File \"/usr/local/lib/python3.8/site-packages/urllib3/connection.py\", line 186, in _new_conn\n    raise NewConnectionError(\nurllib3.exceptions.NewConnectionError: <urllib3.connection.HTTPSConnection object at 0x7fbf0f153d00>: Failed to establish a new connection: [Errno -2] Name or service not known\n\nDuring handling of the above exception, another exception occurred:\n\nTraceback (most recent call last):\n  File \"/usr/local/lib/python3.8/site-packages/requests/adapters.py\", line 486, in send\n    resp = conn.urlopen(\n  File \"/usr/local/lib/python3.8/site-packages/urllib3/connectionpool.py\", line 799, in urlopen\n    retries = retries.increment(\n  File \"/usr/local/lib/python3.8/site-packages/urllib3/util/retry.py\", line 592, in increment\n    raise MaxRetryError(_pool, url, error or ResponseError(cause))\nurllib3.exceptions.MaxRetryError: HTTPSConnectionPool(host='api-t1.fyers.in', port=443): Max retries exceeded with url: /data/symbol-token (Caused by NewConnectionError('<urllib3.connection.HTTPSConnection object at 0x7fbf0f153d00>: Failed to establish a new connection: [Errno -2] Name or service not known'))\n\nDuring handling of the above exception, another exception occurred:\n\nTraceback (most recent call last):\n  File \"/usr/local/lib/python3.8/site-packages/fyers_apiv3/FyersWebsocket/data_ws.py\", line 63, in symbol_to_hsmtoken\n    response = requests.post(\n  File \"/usr/local/lib/python3.8/site-packages/requests/api.py\", line 115, in post\n    return request(\"post\", url, data=data, json=json, **kwargs)\n  File \"/usr/local/lib/python3.8/site-packages/requests/api.py\", line 59, in request\n    return session.request(method=method, url=url, **kwargs)\n  File \"/usr/local/lib/python3.8/site-packages/requests/sessions.py\", line 589, in request\n    resp = self.send(prep, **send_kwargs)\n  File \"/usr/local/lib/python3.8/site-packages/requests/sessions.py\", line 703, in send\n    r = adapter.send(request, **kwargs)\n  File \"/usr/local/lib/python3.8/site-packages/requests/adapters.py\", line 519, in send\n    raise ConnectionError(e, request=request)\nrequests.exceptions.ConnectionError: HTTPSConnectionPool(host='api-t1.fyers.in', port=443): Max retries exceeded with url: /data/symbol-token (Caused by NewConnectionError('<urllib3.connection.HTTPSConnection object at 0x7fbf0f153d00>: Failed to establish a new connection: [Errno -2] Name or service not known'))","exception_name":"ConnectionError"}
{"level":"ERROR","location":"[exception:108] fyers_logger","message":"'NoneType' object is not subscriptable","timestamp":"2024-10-02 12:07:15,525+0530","service":"FyersDataSocket","exception":"Traceback (most recent call last):\n  File \"/usr/local/lib/python3.8/site-packages/websocket/_http.py\", line 155, in _get_addrinfo_list\n    addrinfo_list = socket.getaddrinfo(\n  File \"/usr/local/lib/python3.8/socket.py\", line 918, in getaddrinfo\n    for res in _socket.getaddrinfo(host, port, family, type, proto, flags):\nsocket.gaierror: [Errno -2] Name or service not known\n\nDuring handling of the above exception, another exception occurred:\n\nTraceback (most recent call last):\n  File \"/usr/local/lib/python3.8/site-packages/asgiref/sync.py\", line 349, in main_wrap\n    raise exc_info[1]\n  File \"/usr/local/lib/python3.8/site-packages/websocket/_app.py\", line 412, in setSock\n    self.sock.connect(\n  File \"/usr/local/lib/python3.8/site-packages/websocket/_core.py\", line 249, in connect\n    self.sock, addrs = connect(url, self.sock_opt, proxy_info(**options),\n  File \"/usr/local/lib/python3.8/site-packages/websocket/_http.py\", line 122, in connect\n    addrinfo_list, need_tunnel, auth = _get_addrinfo_list(\n  File \"/usr/local/lib/python3.8/site-packages/websocket/_http.py\", line 167, in _get_addrinfo_list\n    raise WebSocketAddressException(e)\nwebsocket._exceptions.WebSocketAddressException: [Errno -2] Name or service not known\n\nDuring handling of the above exception, another exception occurred:\n\nTraceback (most recent call last):\n  File \"/usr/local/lib/python3.8/site-packages/fyers_apiv3/FyersWebsocket/data_ws.py\", line 1333, in __symbol_conversion\n    if symbol_value[3] != \"\":\nTypeError: 'NoneType' object is not subscriptable","exception_name":"TypeError"}
{"level":"ERROR","location":"[<lambda>:1663] data_ws","message":"[Errno -2] Name or service not known","timestamp":"2024-10-02 12:07:18,532+0530","service":"FyersDataSocket"}
{"level":"ERROR","location":"[exception:108] fyers_logger","message":"HTTPSConnectionPool(host='api-t1.fyers.in', port=443): Max retries exceeded with url: /data/symbol-token (Caused by NewConnectionError('<urllib3.connection.HTTPSConnection object at 0x7fbf0f153820>: Failed to establish a new connection: [Errno -2] Name or service not known'))","timestamp":"2024-10-02 12:07:20,531+0530","service":"FyersDataSocket","exception":"Traceback (most recent call last):\n  File \"/usr/local/lib/python3.8/site-packages/websocket/_http.py\", line 155, in _get_addrinfo_list\n    addrinfo_list = socket.getaddrinfo(\n  File \"/usr/local/lib/python3.8/socket.py\", line 918, in getaddrinfo\n    for res in _socket.getaddrinfo(host, port, family, type, proto, flags):\nsocket.gaierror: [Errno -2] Name or service not known\n\nDuring handling of the above exception, another exception occurred:\n\nTraceback (most recent call last):\n  File \"/usr/local/lib/python3.8/site-packages/asgiref/sync.py\", line 349, in main_wrap\n    raise exc_info[1]\n  File \"/usr/local/lib/python3.8/site-packages/websocket/_app.py\", line 412, in setSock\n    self.sock.connect(\n  File \"/usr/local/lib/python3.8/site-packages/websocket/_core.py\", line 249, in connect\n    self.sock, addrs = connect(url, self.sock_opt, proxy_info(**options),\n  File \"/usr/local/lib/python3.8/site-packages/websocket/_http.py\", line 122, in connect\n    addrinfo_list, need_tunnel, auth = _get_addrinfo_list(\n  File \"/usr/local/lib/python3.8/site-packages/websocket/_http.py\", line 167, in _get_addrinfo_list\n    raise WebSocketAddressException(e)\nwebsocket._exceptions.WebSocketAddressException: [Errno -2] Name or service not known\n\nDuring handling of the above exception, another exception occurred:\n\nTraceback (most recent call last):\n  File \"/usr/local/lib/python3.8/site-packages/urllib3/connection.py\", line 174, in _new_conn\n    conn = connection.create_connection(\n  File \"/usr/local/lib/python3.8/site-packages/urllib3/util/connection.py\", line 72, in create_connection\n    for res in socket.getaddrinfo(host, port, family, socket.SOCK_STREAM):\n  File \"/usr/local/lib/python3.8/socket.py\", line 918, in getaddrinfo\n    for res in _socket.getaddrinfo(host, port, family, type, proto, flags):\nsocket.gaierror: [Errno -2] Name or service not known\n\nDuring handling of the above exception, another exception occurred:\n\nTraceback (most recent call last):\n  File \"/usr/local/lib/python3.8/site-packages/urllib3/connectionpool.py\", line 715, in urlopen\n    httplib_response = self._make_request(\n  File \"/usr/local/lib/python3.8/site-packages/urllib3/connectionpool.py\", line 404, in _make_request\n    self._validate_conn(conn)\n  File \"/usr/local/lib/python3.8/site-packages/urllib3/connectionpool.py\", line 1058, in _validate_conn\n    conn.connect()\n  File \"/usr/local/lib/python3.8/site-packages/urllib3/connection.py\", line 363, in connect\n    self.sock = conn = self._new_conn()\n  File \"/usr/local/lib/python3.8/site-packages/urllib3/connection.py\", line 186, in _new_conn\n    raise NewConnectionError(\nurllib3.exceptions.NewConnectionError: <urllib3.connection.HTTPSConnection object at 0x7fbf0f153820>: Failed to establish a new connection: [Errno -2] Name or service not known\n\nDuring handling of the above exception, another exception occurred:\n\nTraceback (most recent call last):\n  File \"/usr/local/lib/python3.8/site-packages/requests/adapters.py\", line 486, in send\n    resp = conn.urlopen(\n  File \"/usr/local/lib/python3.8/site-packages/urllib3/connectionpool.py\", line 799, in urlopen\n    retries = retries.increment(\n  File \"/usr/local/lib/python3.8/site-packages/urllib3/util/retry.py\", line 592, in increment\n    raise MaxRetryError(_pool, url, error or ResponseError(cause))\nurllib3.exceptions.MaxRetryError: HTTPSConnectionPool(host='api-t1.fyers.in', port=443): Max retries exceeded with url: /data/symbol-token (Caused by NewConnectionError('<urllib3.connection.HTTPSConnection object at 0x7fbf0f153820>: Failed to establish a new connection: [Errno -2] Name or service not known'))\n\nDuring handling of the above exception, another exception occurred:\n\nTraceback (most recent call last):\n  File \"/usr/local/lib/python3.8/site-packages/fyers_apiv3/FyersWebsocket/data_ws.py\", line 63, in symbol_to_hsmtoken\n    response = requests.post(\n  File \"/usr/local/lib/python3.8/site-packages/requests/api.py\", line 115, in post\n    return request(\"post\", url, data=data, json=json, **kwargs)\n  File \"/usr/local/lib/python3.8/site-packages/requests/api.py\", line 59, in request\n    return session.request(method=method, url=url, **kwargs)\n  File \"/usr/local/lib/python3.8/site-packages/requests/sessions.py\", line 589, in request\n    resp = self.send(prep, **send_kwargs)\n  File \"/usr/local/lib/python3.8/site-packages/requests/sessions.py\", line 703, in send\n    r = adapter.send(request, **kwargs)\n  File \"/usr/local/lib/python3.8/site-packages/requests/adapters.py\", line 519, in send\n    raise ConnectionError(e, request=request)\nrequests.exceptions.ConnectionError: HTTPSConnectionPool(host='api-t1.fyers.in', port=443): Max retries exceeded with url: /data/symbol-token (Caused by NewConnectionError('<urllib3.connection.HTTPSConnection object at 0x7fbf0f153820>: Failed to establish a new connection: [Errno -2] Name or service not known'))","exception_name":"ConnectionError"}
{"level":"ERROR","location":"[exception:108] fyers_logger","message":"'NoneType' object is not subscriptable","timestamp":"2024-10-02 12:07:20,533+0530","service":"FyersDataSocket","exception":"Traceback (most recent call last):\n  File \"/usr/local/lib/python3.8/site-packages/websocket/_http.py\", line 155, in _get_addrinfo_list\n    addrinfo_list = socket.getaddrinfo(\n  File \"/usr/local/lib/python3.8/socket.py\", line 918, in getaddrinfo\n    for res in _socket.getaddrinfo(host, port, family, type, proto, flags):\nsocket.gaierror: [Errno -2] Name or service not known\n\nDuring handling of the above exception, another exception occurred:\n\nTraceback (most recent call last):\n  File \"/usr/local/lib/python3.8/site-packages/asgiref/sync.py\", line 349, in main_wrap\n    raise exc_info[1]\n  File \"/usr/local/lib/python3.8/site-packages/websocket/_app.py\", line 412, in setSock\n    self.sock.connect(\n  File \"/usr/local/lib/python3.8/site-packages/websocket/_core.py\", line 249, in connect\n    self.sock, addrs = connect(url, self.sock_opt, proxy_info(**options),\n  File \"/usr/local/lib/python3.8/site-packages/websocket/_http.py\", line 122, in connect\n    addrinfo_list, need_tunnel, auth = _get_addrinfo_list(\n  File \"/usr/local/lib/python3.8/site-packages/websocket/_http.py\", line 167, in _get_addrinfo_list\n    raise WebSocketAddressException(e)\nwebsocket._exceptions.WebSocketAddressException: [Errno -2] Name or service not known\n\nDuring handling of the above exception, another exception occurred:\n\nTraceback (most recent call last):\n  File \"/usr/local/lib/python3.8/site-packages/fyers_apiv3/FyersWebsocket/data_ws.py\", line 1333, in __symbol_conversion\n    if symbol_value[3] != \"\":\nTypeError: 'NoneType' object is not subscriptable","exception_name":"TypeError"}
{"level":"ERROR","location":"[unsubscribe:1757] data_ws","message":{"code":-300,"message":"Please provide a valid symbol","s":"error"},"timestamp":"2024-10-02 13:31:31,381+0530","service":"FyersDataSocket"}
